<?xml version="1.0"?>
<robot name="robot_disco" xmlns:xacro="http://www.ros.org/wiki/xacro" >

<!-- Colors -->

    <material name="black">
        <color rgba="0.0 0.0 0.0 1" />
    </material>

    <material name="grey">
        <color rgba="0.7 0.7 0.7 1" />
    </material>

    <material name="white">
        <color rgba="1.0 1.0 1.0 1" />
    </material>

<!-- Base frame of the robot -->
    <link name="base_footprint" />
        
    <link name="base_link">
        <visual>
            <geometry>
                <box size="0.41 0.402 0.250" />
            </geometry>
            <origin xyz="0.0 0.0 0.125" rpy="0.0 0.0 0.0" />
            <material name="black" />
        </visual>
    </link>

    <joint name="base_joint" type="fixed">
        <parent link="base_footprint"/>
        <child link="base_link"/>
        <origin xyz="0.0 0.0 0.172" rpy="0.0 0.0 0.0"/>
    </joint>

    <link name="piller_front_left">
        <visual>
            <geometry>
                <box size="0.012 0.012 0.650"/>    
            </geometry>
            <origin xyz="0.0 0.0 0.325" rpy="0.0 0.0 0.0"/>
            <material name="white" />
        </visual>
    </link>

    <joint name="base_to_piller_front_left" type="fixed">
        <parent link="base_link"/>
        <child link="piller_front_left"/>
        <origin xyz="0.198 0.195 0.25" rpy="0.0 0.0 0.0"/>
    </joint>

        <link name="piller_front_right">
        <visual>
            <geometry>
                <box size="0.012 0.012 0.650"/>    
            </geometry>
            <origin xyz="0.0 0.0 0.325" rpy="0.0 0.0 0.0"/>
            <material name="white" />
        </visual>
    </link>

    <joint name="base_to_piller_front_right" type="fixed">
        <parent link="base_link"/>
        <child link="piller_front_right"/>
        <origin xyz="-0.198 0.195 0.25" rpy="0.0 0.0 0.0"/>
    </joint>
    
        <link name="piller_back_left">
        <visual>
            <geometry>
                <box size="0.012 0.012 0.650"/>    
            </geometry>
            <origin xyz="0.0 0.0 0.325" rpy="0.0 0.0 0.0"/>
            <material name="white" />
        </visual>
    </link>

    <joint name="base_to_piller_back_left" type="fixed">
        <parent link="base_link"/>
        <child link="piller_back_left"/>
        <origin xyz="0.198 -0.195 0.25" rpy="0.0 0.0 0.0"/>
    </joint>
    
    <link name="piller_back_right">
        <visual>
            <geometry>
                <box size="0.012 0.012 0.650"/>    
            </geometry>
            <origin xyz="0.0 0.0 0.325" rpy="0.0 0.0 0.0"/>
            <material name="white" />
        </visual>
    </link>

    <joint name="base_to_piller_back_right" type="fixed">
        <parent link="base_link"/>
        <child link="piller_back_right"/>
        <origin xyz="-0.198 -0.195 0.25" rpy="0.0 0.0 0.0"/>
    </joint>


    <link name="top">
        <visual>
            <geometry>
                <box size="0.41 0.402 0.030"/>    
            </geometry>
            <origin xyz="0.0 0.0 0.015" rpy="0.0 0.0 0.0"/>
            <material name="white" />
        </visual>
    </link>

    <joint name="base_to_top" type="fixed">
        <parent link="base_link"/>
        <child link="top"/>
        <origin xyz="0 0 0.9" rpy="0.0 0.0 0.0"/>
    </joint>

<!-- Wheels -->

    <link name="wheel_left">
        <visual>
            <geometry>
                <cylinder radius="0.172" length="0.07"/> 
            </geometry>
            <origin xyz="0.0 0.0 0.0" rpy="0 1.57 0.0"/>
            <material name="grey" />
        </visual>
    </link>

    <joint name="base_to_wheel_left" type="continuous">
        <parent link="base_link"/>
        <child link="wheel_left"/>
        <origin xyz="-0.272 0.0 0.0" rpy="0.0 0.0 0.0"/>
        <axis xyz="1.0 0.0 0.0"/>
    </joint>

    <link name="wheel_right">
        <visual>
            <geometry>
                <cylinder radius="0.172" length="0.07"/> 
            </geometry>
            <origin xyz="0.0 0.0 0.0" rpy="0 1.57 0.0"/>
            <material name="grey" />
        </visual>
    </link>

    <joint name="base_to_wheel_right" type="continuous">
        <parent link="base_link"/>
        <child link="wheel_right"/>
        <origin xyz="0.272 0.0 0.0" rpy="0.0 0.0 0.0"/>
        <axis xyz="1.0 0.0 0.0"/>
    </joint>


    <!-- Front Right Caster Assembly -->

    <link name="caster_mount_front_right">
        <visual>
            <geometry>
                <cylinder radius="0.0125" length="0.06"/> 
            </geometry>
            <origin xyz="0.0 0.0 -0.03" rpy="0.0 0.0 0.0"/>
            <material name="black" />
        </visual>
    </link>

    <joint name="base_to_caster_mount_front_right" type="fixed">
        <parent link="base_link"/>
        <child link="caster_mount_front_right"/>
        <origin xyz="0.241 0.34 0.04" rpy="0.0 0.0 0.0"/>
    </joint>

    <link name="caster_plate_front_right">
        <visual>
            <geometry>
                <box size="0.095 0.045 0.010"/>
            </geometry>
            <origin xyz="0.0 0.015 0.00" rpy="0.0 0.0 1.57"/>
            <material name="black" />
        </visual>
    </link>

    <joint name="caster_mount_to_plate_front_right" type="continuous">
        <parent link="caster_mount_front_right"/>
        <child link="caster_plate_front_right"/>
        <origin xyz="0.0 0.0 -0.06" rpy="0.0 0.0 0.0"/>
        <axis xyz="0.0 0.0 1.0"/>
    </joint>

    <link name="caster_wheel_front_right">
        <visual>
            <geometry>
               <cylinder radius="0.075" length="0.050"/>
            </geometry>
            <origin xyz="0.0 0.0 0.00" rpy="0.0 1.57 0.0"/>
            <material name="grey" />
        </visual>
    </link>

    <joint name="caster_plate_to_wheel_front_right" type="continuous">
        <parent link="caster_plate_front_right"/>
        <child link="caster_wheel_front_right"/>
        <origin xyz="0.0 0.03 -0.081" rpy="0.0 0.0 0.0"/>
        <axis xyz="1.0 0.0 0.0"/>
    </joint>


 <!-- Front Left Caster Assembly -->

    <link name="caster_mount_front_left">
        <visual>
            <geometry>
                <cylinder radius="0.0125" length="0.06"/> 
            </geometry>
            <origin xyz="0.0 0.0 -0.03" rpy="0.0 0.0 0.0"/>
            <material name="black" />
        </visual>
    </link>

    <joint name="base_to_caster_mount_front_left" type="fixed">
        <parent link="base_link"/>
        <child link="caster_mount_front_left"/>
        <origin xyz="-0.241 0.34 0.04" rpy="0.0 0.0 0.0"/>
    </joint>

    <link name="caster_plate_front_left">
        <visual>
            <geometry>
                <box size="0.095 0.045 0.010"/>
            </geometry>
            <origin xyz="0.0 0.015 0.00" rpy="0.0 0.0 1.57"/>
            <material name="black" />
        </visual>
    </link>

    <joint name="caster_mount_to_plate_front_left" type="continuous">
        <parent link="caster_mount_front_left"/>
        <child link="caster_plate_front_left"/>
        <origin xyz="0.0 0.0 -0.06" rpy="0.0 0.0 0.0"/>
        <axis xyz="0.0 0.0 1.0"/>
    </joint>

    <link name="caster_wheel_front_left">
        <visual>
            <geometry>
               <cylinder radius="0.075" length="0.050"/>
            </geometry>
            <origin xyz="0.0 0.0 0.00" rpy="0.0 1.57 0.0"/>
            <material name="grey" />
        </visual>
    </link>

    <joint name="caster_plate_to_wheel_front_left" type="continuous">
        <parent link="caster_plate_front_left"/>
        <child link="caster_wheel_front_left"/>
        <origin xyz="0.0 0.03 -0.081" rpy="0.0 0.0 0.0"/>
        <axis xyz="1.0 0.0 0.0"/>
    </joint>





 <!-- Back Left Caster Assembly -->

    <link name="caster_mount_back_left">
        <visual>
            <geometry>
                <cylinder radius="0.0125" length="0.065"/> 
            </geometry>
            <origin xyz="0.0 0.0 -0.0325" rpy="0.0 0.0 0.0"/>
            <material name="black" />
        </visual>
    </link>

    <joint name="base_to_caster_mount_back_left" type="fixed">
        <parent link="base_link"/>
        <child link="caster_mount_back_left"/>
        <origin xyz="0.115 -0.361 0.018" rpy="0.0 0.0 0.0"/>
    </joint>

    <link name="caster_plate_back_left">
        <visual>
            <geometry>
                <box size="0.095 0.045 0.010"/>
            </geometry>
            <origin xyz="0.0 0.015 0.00" rpy="0.0 0.0 1.57"/>
            <material name="black" />
        </visual>
    </link>

    <joint name="caster_mount_to_plate_back_left" type="continuous">
        <parent link="caster_mount_back_left"/>
        <child link="caster_plate_back_left"/>
        <origin xyz="0.0 0.0 -0.06" rpy="0.0 0.0 0.0"/>
        <axis xyz="0.0 0.0 1.0"/>
    </joint>

    <link name="caster_wheel_back_left">
        <visual>
            <geometry>
               <cylinder radius="0.065" length="0.040"/>
            </geometry>
            <origin xyz="0.0 0.0 0.00" rpy="0.0 1.57 0.0"/>
            <material name="grey" />
        </visual>
    </link>

    <joint name="caster_plate_to_wheel_back_left" type="continuous">
        <parent link="caster_plate_back_left"/>
        <child link="caster_wheel_back_left"/>
        <origin xyz="0.0 0.03 -0.071" rpy="0.0 0.0 0.0"/>
        <axis xyz="1.0 0.0 0.0"/>
    </joint>

 <!-- Back Right Caster Assembly -->

    <link name="caster_mount_back_right">
        <visual>
            <geometry>
                <cylinder radius="0.0125" length="0.065"/> 
            </geometry>
            <origin xyz="0.0 0.0 -0.0325" rpy="0.0 0.0 0.0"/>
            <material name="black" />
        </visual>
    </link>

    <joint name="base_to_caster_mount_back_right" type="fixed">
        <parent link="base_link"/>
        <child link="caster_mount_back_right"/>
        <origin xyz="-0.115 -0.361 0.018" rpy="0.0 0.0 0.0"/>
    </joint>

    <link name="caster_plate_back_right">
        <visual>
            <geometry>
                <box size="0.095 0.045 0.010"/>
            </geometry>
            <origin xyz="0.0 0.015 0.00" rpy="0.0 0.0 1.57"/>
            <material name="black" />
        </visual>
    </link>

    <joint name="caster_mount_to_plate_back_right" type="continuous">
        <parent link="caster_mount_back_right"/>
        <child link="caster_plate_back_right"/>
        <origin xyz="0.0 0.0 -0.06" rpy="0.0 0.0 0.0"/>
        <axis xyz="0.0 0.0 1.0"/>
    </joint>

    <link name="caster_wheel_back_right">
        <visual>
            <geometry>
               <cylinder radius="0.065" length="0.040"/>
            </geometry>
            <origin xyz="0.0 0.0 0.00" rpy="0.0 1.57 0.0"/>
            <material name="grey" />
        </visual>
    </link>

    <joint name="caster_plate_to_wheel_back_right" type="continuous">
        <parent link="caster_plate_back_right"/>
        <child link="caster_wheel_back_right"/>
        <origin xyz="0.0 0.03 -0.071" rpy="0.0 0.0 0.0"/>
        <axis xyz="1.0 0.0 0.0"/>
    </joint>
</robot>